{
 "cells": [
  {
   "cell_type": "code",
   "execution_count": 1,
   "metadata": {},
   "outputs": [
    {
     "name": "stdout",
     "output_type": "stream",
     "text": [
      "Collecting kagglehub\n",
      "  Downloading kagglehub-0.3.6-py3-none-any.whl.metadata (30 kB)\n",
      "Requirement already satisfied: packaging in /home/gitpod/.pyenv/versions/3.12.7/lib/python3.12/site-packages (from kagglehub) (24.1)\n",
      "Requirement already satisfied: requests in /home/gitpod/.pyenv/versions/3.12.7/lib/python3.12/site-packages (from kagglehub) (2.32.3)\n",
      "Collecting tqdm (from kagglehub)\n",
      "  Downloading tqdm-4.67.1-py3-none-any.whl.metadata (57 kB)\n",
      "Requirement already satisfied: charset-normalizer<4,>=2 in /home/gitpod/.pyenv/versions/3.12.7/lib/python3.12/site-packages (from requests->kagglehub) (3.4.0)\n",
      "Requirement already satisfied: idna<4,>=2.5 in /home/gitpod/.pyenv/versions/3.12.7/lib/python3.12/site-packages (from requests->kagglehub) (3.10)\n",
      "Requirement already satisfied: urllib3<3,>=1.21.1 in /home/gitpod/.pyenv/versions/3.12.7/lib/python3.12/site-packages (from requests->kagglehub) (2.2.3)\n",
      "Requirement already satisfied: certifi>=2017.4.17 in /home/gitpod/.pyenv/versions/3.12.7/lib/python3.12/site-packages (from requests->kagglehub) (2024.8.30)\n",
      "Downloading kagglehub-0.3.6-py3-none-any.whl (51 kB)\n",
      "Downloading tqdm-4.67.1-py3-none-any.whl (78 kB)\n",
      "Installing collected packages: tqdm, kagglehub\n",
      "Successfully installed kagglehub-0.3.6 tqdm-4.67.1\n",
      "\n",
      "\u001b[1m[\u001b[0m\u001b[34;49mnotice\u001b[0m\u001b[1;39;49m]\u001b[0m\u001b[39;49m A new release of pip is available: \u001b[0m\u001b[31;49m24.2\u001b[0m\u001b[39;49m -> \u001b[0m\u001b[32;49m24.3.1\u001b[0m\n",
      "\u001b[1m[\u001b[0m\u001b[34;49mnotice\u001b[0m\u001b[1;39;49m]\u001b[0m\u001b[39;49m To update, run: \u001b[0m\u001b[32;49mpip install --upgrade pip\u001b[0m\n",
      "Note: you may need to restart the kernel to use updated packages.\n"
     ]
    }
   ],
   "source": [
    "%pip install kagglehub"
   ]
  },
  {
   "cell_type": "code",
   "execution_count": 9,
   "metadata": {},
   "outputs": [],
   "source": [
    "target_path = \"/workspace/plant_disease_detection/dataset\""
   ]
  },
  {
   "cell_type": "code",
   "execution_count": 10,
   "metadata": {},
   "outputs": [
    {
     "ename": "KaggleApiHTTPError",
     "evalue": "404 Client Error.\n\nResource not found at URL: https://www.kaggle.com/datasets/rashikrahmanpritom/plant-disease-recognition-dataset/versions/1\nThe server reported the following issues: Not found\nPlease make sure you specified the correct resource identifiers.",
     "output_type": "error",
     "traceback": [
      "\u001b[0;31m---------------------------------------------------------------------------\u001b[0m",
      "\u001b[0;31mHTTPError\u001b[0m                                 Traceback (most recent call last)",
      "File \u001b[0;32m~/.pyenv/versions/3.12.7/lib/python3.12/site-packages/kagglehub/exceptions.py:62\u001b[0m, in \u001b[0;36mkaggle_api_raise_for_status\u001b[0;34m(response, resource_handle)\u001b[0m\n\u001b[1;32m     61\u001b[0m \u001b[38;5;28;01mtry\u001b[39;00m:\n\u001b[0;32m---> 62\u001b[0m     \u001b[43mresponse\u001b[49m\u001b[38;5;241;43m.\u001b[39;49m\u001b[43mraise_for_status\u001b[49m\u001b[43m(\u001b[49m\u001b[43m)\u001b[49m\n\u001b[1;32m     63\u001b[0m \u001b[38;5;28;01mexcept\u001b[39;00m requests\u001b[38;5;241m.\u001b[39mHTTPError \u001b[38;5;28;01mas\u001b[39;00m e:\n",
      "File \u001b[0;32m~/.pyenv/versions/3.12.7/lib/python3.12/site-packages/requests/models.py:1024\u001b[0m, in \u001b[0;36mResponse.raise_for_status\u001b[0;34m(self)\u001b[0m\n\u001b[1;32m   1023\u001b[0m \u001b[38;5;28;01mif\u001b[39;00m http_error_msg:\n\u001b[0;32m-> 1024\u001b[0m     \u001b[38;5;28;01mraise\u001b[39;00m HTTPError(http_error_msg, response\u001b[38;5;241m=\u001b[39m\u001b[38;5;28mself\u001b[39m)\n",
      "\u001b[0;31mHTTPError\u001b[0m: 404 Client Error: Not Found for url: https://www.kaggle.com/api/v1/datasets/download/rashikrahmanpritom/plant-disease-recognition-dataset?dataset_version_number=1&file_name=/workspace/plant_disease_detection/dataset",
      "\nThe above exception was the direct cause of the following exception:\n",
      "\u001b[0;31mKaggleApiHTTPError\u001b[0m                        Traceback (most recent call last)",
      "Cell \u001b[0;32mIn[10], line 4\u001b[0m\n\u001b[1;32m      1\u001b[0m \u001b[38;5;28;01mimport\u001b[39;00m \u001b[38;5;21;01mkagglehub\u001b[39;00m\n\u001b[1;32m      3\u001b[0m \u001b[38;5;66;03m# Download latest version\u001b[39;00m\n\u001b[0;32m----> 4\u001b[0m path \u001b[38;5;241m=\u001b[39m \u001b[43mkagglehub\u001b[49m\u001b[38;5;241;43m.\u001b[39;49m\u001b[43mdataset_download\u001b[49m\u001b[43m(\u001b[49m\u001b[38;5;124;43m\"\u001b[39;49m\u001b[38;5;124;43mrashikrahmanpritom/plant-disease-recognition-dataset\u001b[39;49m\u001b[38;5;124;43m\"\u001b[39;49m\u001b[43m,\u001b[49m\u001b[43m \u001b[49m\u001b[43mpath\u001b[49m\u001b[38;5;241;43m=\u001b[39;49m\u001b[43mtarget_path\u001b[49m\u001b[43m)\u001b[49m\n\u001b[1;32m      6\u001b[0m \u001b[38;5;28mprint\u001b[39m(\u001b[38;5;124m\"\u001b[39m\u001b[38;5;124mPath to dataset files:\u001b[39m\u001b[38;5;124m\"\u001b[39m, path)\n",
      "File \u001b[0;32m~/.pyenv/versions/3.12.7/lib/python3.12/site-packages/kagglehub/datasets.py:40\u001b[0m, in \u001b[0;36mdataset_download\u001b[0;34m(handle, path, force_download)\u001b[0m\n\u001b[1;32m     38\u001b[0m h \u001b[38;5;241m=\u001b[39m parse_dataset_handle(handle)\n\u001b[1;32m     39\u001b[0m logger\u001b[38;5;241m.\u001b[39minfo(\u001b[38;5;124mf\u001b[39m\u001b[38;5;124m\"\u001b[39m\u001b[38;5;124mDownloading Dataset: \u001b[39m\u001b[38;5;132;01m{\u001b[39;00mh\u001b[38;5;241m.\u001b[39mto_url()\u001b[38;5;132;01m}\u001b[39;00m\u001b[38;5;124m ...\u001b[39m\u001b[38;5;124m\"\u001b[39m, extra\u001b[38;5;241m=\u001b[39m{\u001b[38;5;241m*\u001b[39m\u001b[38;5;241m*\u001b[39mEXTRA_CONSOLE_BLOCK})\n\u001b[0;32m---> 40\u001b[0m \u001b[38;5;28;01mreturn\u001b[39;00m \u001b[43mregistry\u001b[49m\u001b[38;5;241;43m.\u001b[39;49m\u001b[43mdataset_resolver\u001b[49m\u001b[43m(\u001b[49m\u001b[43mh\u001b[49m\u001b[43m,\u001b[49m\u001b[43m \u001b[49m\u001b[43mpath\u001b[49m\u001b[43m,\u001b[49m\u001b[43m \u001b[49m\u001b[43mforce_download\u001b[49m\u001b[38;5;241;43m=\u001b[39;49m\u001b[43mforce_download\u001b[49m\u001b[43m)\u001b[49m\n",
      "File \u001b[0;32m~/.pyenv/versions/3.12.7/lib/python3.12/site-packages/kagglehub/registry.py:23\u001b[0m, in \u001b[0;36mMultiImplRegistry.__call__\u001b[0;34m(self, *args, **kwargs)\u001b[0m\n\u001b[1;32m     21\u001b[0m \u001b[38;5;28;01mfor\u001b[39;00m impl \u001b[38;5;129;01min\u001b[39;00m \u001b[38;5;28mreversed\u001b[39m(\u001b[38;5;28mself\u001b[39m\u001b[38;5;241m.\u001b[39m_impls):\n\u001b[1;32m     22\u001b[0m     \u001b[38;5;28;01mif\u001b[39;00m impl\u001b[38;5;241m.\u001b[39mis_supported(\u001b[38;5;241m*\u001b[39margs, \u001b[38;5;241m*\u001b[39m\u001b[38;5;241m*\u001b[39mkwargs):\n\u001b[0;32m---> 23\u001b[0m         \u001b[38;5;28;01mreturn\u001b[39;00m \u001b[43mimpl\u001b[49m\u001b[43m(\u001b[49m\u001b[38;5;241;43m*\u001b[39;49m\u001b[43margs\u001b[49m\u001b[43m,\u001b[49m\u001b[43m \u001b[49m\u001b[38;5;241;43m*\u001b[39;49m\u001b[38;5;241;43m*\u001b[39;49m\u001b[43mkwargs\u001b[49m\u001b[43m)\u001b[49m\n\u001b[1;32m     24\u001b[0m     \u001b[38;5;28;01melse\u001b[39;00m:\n\u001b[1;32m     25\u001b[0m         fails\u001b[38;5;241m.\u001b[39mappend(\u001b[38;5;28mtype\u001b[39m(impl)\u001b[38;5;241m.\u001b[39m\u001b[38;5;18m__name__\u001b[39m)\n",
      "File \u001b[0;32m~/.pyenv/versions/3.12.7/lib/python3.12/site-packages/kagglehub/http_resolver.py:120\u001b[0m, in \u001b[0;36mDatasetHttpResolver.__call__\u001b[0;34m(self, h, path, force_download)\u001b[0m\n\u001b[1;32m    117\u001b[0m \u001b[38;5;28;01mif\u001b[39;00m path:\n\u001b[1;32m    118\u001b[0m     \u001b[38;5;66;03m# Downloading a single file.\u001b[39;00m\n\u001b[1;32m    119\u001b[0m     os\u001b[38;5;241m.\u001b[39mmakedirs(os\u001b[38;5;241m.\u001b[39mpath\u001b[38;5;241m.\u001b[39mdirname(out_path), exist_ok\u001b[38;5;241m=\u001b[39m\u001b[38;5;28;01mTrue\u001b[39;00m)\n\u001b[0;32m--> 120\u001b[0m     \u001b[43mapi_client\u001b[49m\u001b[38;5;241;43m.\u001b[39;49m\u001b[43mdownload_file\u001b[49m\u001b[43m(\u001b[49m\u001b[43murl_path\u001b[49m\u001b[43m \u001b[49m\u001b[38;5;241;43m+\u001b[39;49m\u001b[43m \u001b[49m\u001b[38;5;124;43m\"\u001b[39;49m\u001b[38;5;124;43m&file_name=\u001b[39;49m\u001b[38;5;124;43m\"\u001b[39;49m\u001b[43m \u001b[49m\u001b[38;5;241;43m+\u001b[39;49m\u001b[43m \u001b[49m\u001b[43mpath\u001b[49m\u001b[43m,\u001b[49m\u001b[43m \u001b[49m\u001b[43mout_path\u001b[49m\u001b[43m,\u001b[49m\u001b[43m \u001b[49m\u001b[43mh\u001b[49m\u001b[43m,\u001b[49m\u001b[43m \u001b[49m\u001b[43mextract_auto_compressed_file\u001b[49m\u001b[38;5;241;43m=\u001b[39;49m\u001b[38;5;28;43;01mTrue\u001b[39;49;00m\u001b[43m)\u001b[49m\n\u001b[1;32m    121\u001b[0m \u001b[38;5;28;01melse\u001b[39;00m:\n\u001b[1;32m    122\u001b[0m     \u001b[38;5;66;03m# TODO(b/345800027) Implement parallel download when < 25 files in databundle.\u001b[39;00m\n\u001b[1;32m    123\u001b[0m     \u001b[38;5;66;03m# Downloading the full archived bundle.\u001b[39;00m\n\u001b[1;32m    124\u001b[0m     archive_path \u001b[38;5;241m=\u001b[39m get_cached_archive_path(h)\n",
      "File \u001b[0;32m~/.pyenv/versions/3.12.7/lib/python3.12/site-packages/kagglehub/clients.py:160\u001b[0m, in \u001b[0;36mKaggleApiV1Client.download_file\u001b[0;34m(self, path, out_file, resource_handle, cached_path, extract_auto_compressed_file)\u001b[0m\n\u001b[1;32m    152\u001b[0m url \u001b[38;5;241m=\u001b[39m \u001b[38;5;28mself\u001b[39m\u001b[38;5;241m.\u001b[39m_build_url(path)\n\u001b[1;32m    153\u001b[0m \u001b[38;5;28;01mwith\u001b[39;00m requests\u001b[38;5;241m.\u001b[39mget(\n\u001b[1;32m    154\u001b[0m     url,\n\u001b[1;32m    155\u001b[0m     headers\u001b[38;5;241m=\u001b[39m{\u001b[38;5;124m\"\u001b[39m\u001b[38;5;124mUser-Agent\u001b[39m\u001b[38;5;124m\"\u001b[39m: get_user_agent()},\n\u001b[0;32m   (...)\u001b[0m\n\u001b[1;32m    158\u001b[0m     timeout\u001b[38;5;241m=\u001b[39m(DEFAULT_CONNECT_TIMEOUT, DEFAULT_READ_TIMEOUT),\n\u001b[1;32m    159\u001b[0m ) \u001b[38;5;28;01mas\u001b[39;00m response:\n\u001b[0;32m--> 160\u001b[0m     \u001b[43mkaggle_api_raise_for_status\u001b[49m\u001b[43m(\u001b[49m\u001b[43mresponse\u001b[49m\u001b[43m,\u001b[49m\u001b[43m \u001b[49m\u001b[43mresource_handle\u001b[49m\u001b[43m)\u001b[49m\n\u001b[1;32m    161\u001b[0m     total_size \u001b[38;5;241m=\u001b[39m \u001b[38;5;28mint\u001b[39m(response\u001b[38;5;241m.\u001b[39mheaders[\u001b[38;5;124m\"\u001b[39m\u001b[38;5;124mContent-Length\u001b[39m\u001b[38;5;124m\"\u001b[39m])\n\u001b[1;32m    162\u001b[0m     size_read \u001b[38;5;241m=\u001b[39m \u001b[38;5;241m0\u001b[39m\n",
      "File \u001b[0;32m~/.pyenv/versions/3.12.7/lib/python3.12/site-packages/kagglehub/exceptions.py:102\u001b[0m, in \u001b[0;36mkaggle_api_raise_for_status\u001b[0;34m(response, resource_handle)\u001b[0m\n\u001b[1;32m     93\u001b[0m     message \u001b[38;5;241m=\u001b[39m (\n\u001b[1;32m     94\u001b[0m         \u001b[38;5;124mf\u001b[39m\u001b[38;5;124m\"\u001b[39m\u001b[38;5;132;01m{\u001b[39;00mresponse\u001b[38;5;241m.\u001b[39mstatus_code\u001b[38;5;132;01m}\u001b[39;00m\u001b[38;5;124m Client Error.\u001b[39m\u001b[38;5;124m\"\u001b[39m\n\u001b[1;32m     95\u001b[0m         \u001b[38;5;124m\"\u001b[39m\u001b[38;5;130;01m\\n\u001b[39;00m\u001b[38;5;130;01m\\n\u001b[39;00m\u001b[38;5;124m\"\u001b[39m\n\u001b[0;32m   (...)\u001b[0m\n\u001b[1;32m     98\u001b[0m         \u001b[38;5;124m\"\u001b[39m\u001b[38;5;124mPlease make sure you specified the correct resource identifiers.\u001b[39m\u001b[38;5;124m\"\u001b[39m\n\u001b[1;32m     99\u001b[0m     )\n\u001b[1;32m    101\u001b[0m \u001b[38;5;66;03m# Default handling\u001b[39;00m\n\u001b[0;32m--> 102\u001b[0m \u001b[38;5;28;01mraise\u001b[39;00m KaggleApiHTTPError(message, response\u001b[38;5;241m=\u001b[39mresponse) \u001b[38;5;28;01mfrom\u001b[39;00m \u001b[38;5;21;01me\u001b[39;00m\n",
      "\u001b[0;31mKaggleApiHTTPError\u001b[0m: 404 Client Error.\n\nResource not found at URL: https://www.kaggle.com/datasets/rashikrahmanpritom/plant-disease-recognition-dataset/versions/1\nThe server reported the following issues: Not found\nPlease make sure you specified the correct resource identifiers."
     ]
    }
   ],
   "source": [
    "import kagglehub\n",
    "\n",
    "# Download latest version\n",
    "path = kagglehub.dataset_download(\"rashikrahmanpritom/plant-disease-recognition-dataset\", path=target_path)\n",
    "\n",
    "print(\"Path to dataset files:\", path)"
   ]
  },
  {
   "cell_type": "code",
   "execution_count": null,
   "metadata": {},
   "outputs": [],
   "source": []
  }
 ],
 "metadata": {
  "kernelspec": {
   "display_name": "Python 3",
   "language": "python",
   "name": "python3"
  },
  "language_info": {
   "codemirror_mode": {
    "name": "ipython",
    "version": 3
   },
   "file_extension": ".py",
   "mimetype": "text/x-python",
   "name": "python",
   "nbconvert_exporter": "python",
   "pygments_lexer": "ipython3",
   "version": "3.12.7"
  }
 },
 "nbformat": 4,
 "nbformat_minor": 2
}
